<?xml version="1.0" encoding="UTF-8"?>
<testng-results ignored="0" total="4" passed="0" failed="4" skipped="0">
  <reporter-output>
  </reporter-output>
  <suite started-at="2020-11-29T18:41:23 GMT" name="Default suite" finished-at="2020-11-29T18:41:41 GMT" duration-ms="17284">
    <groups>
    </groups>
    <test started-at="2020-11-29T18:41:23 GMT" name="Default test" finished-at="2020-11-29T18:41:41 GMT" duration-ms="17284">
      <class name="com.autopractice.tests.DpTest">
        <test-method is-config="true" signature="launchBrowser()[pri:0, instance:com.autopractice.tests.DpTest@31c88ec8]" started-at="2020-11-29T18:41:23 GMT" name="launchBrowser" finished-at="2020-11-29T18:41:30 GMT" duration-ms="6122" status="PASS">
          <reporter-output>
          </reporter-output>
        </test-method> <!-- launchBrowser -->
        <test-method is-config="true" signature="enterURL()[pri:0, instance:com.autopractice.tests.DpTest@31c88ec8]" started-at="2020-11-29T18:41:30 GMT" name="enterURL" finished-at="2020-11-29T18:41:33 GMT" duration-ms="3384" status="PASS">
          <reporter-output>
          </reporter-output>
        </test-method> <!-- enterURL -->
        <test-method signature="testLoginWithValidCredentials(java.lang.String, java.lang.String)[pri:0, instance:com.autopractice.tests.DpTest@31c88ec8]" started-at="2020-11-29T18:41:33 GMT" name="testLoginWithValidCredentials" data-provider="UserData" finished-at="2020-11-29T18:41:34 GMT" duration-ms="1221" status="FAIL">
          <params>
            <param index="0">
              <value>
                <![CDATA[test1]]>
              </value>
            </param>
            <param index="1">
              <value>
                <![CDATA[pass1]]>
              </value>
            </param>
          </params>
          <exception class="java.lang.AssertionError">
            <message>
              <![CDATA[The following asserts failed:
expected [My Account - My Store] but found [Login - My Store]]]>
            </message>
            <full-stacktrace>
              <![CDATA[java.lang.AssertionError: The following asserts failed:
expected [My Account - My Store] but found [Login - My Store]
at org.testng.asserts.SoftAssert.assertAll(SoftAssert.java:47)
at org.testng.asserts.SoftAssert.assertAll(SoftAssert.java:31)
at com.autopractice.tests.DpTest.testLoginWithValidCredentials(DpTest.java:76)
at java.base/jdk.internal.reflect.NativeMethodAccessorImpl.invoke0(Native Method)
at java.base/jdk.internal.reflect.NativeMethodAccessorImpl.invoke(NativeMethodAccessorImpl.java:62)
at java.base/jdk.internal.reflect.DelegatingMethodAccessorImpl.invoke(DelegatingMethodAccessorImpl.java:43)
at java.base/java.lang.reflect.Method.invoke(Method.java:564)
at org.testng.internal.MethodInvocationHelper.invokeMethod(MethodInvocationHelper.java:132)
at org.testng.internal.TestInvoker.invokeMethod(TestInvoker.java:599)
at org.testng.internal.TestInvoker.invokeTestMethod(TestInvoker.java:174)
at org.testng.internal.MethodRunner.runInSequence(MethodRunner.java:46)
at org.testng.internal.TestInvoker$MethodInvocationAgent.invoke(TestInvoker.java:822)
at org.testng.internal.TestInvoker.invokeTestMethods(TestInvoker.java:147)
at org.testng.internal.TestMethodWorker.invokeTestMethods(TestMethodWorker.java:146)
at org.testng.internal.TestMethodWorker.run(TestMethodWorker.java:128)
at java.base/java.util.ArrayList.forEach(ArrayList.java:1511)
at org.testng.TestRunner.privateRun(TestRunner.java:764)
at org.testng.TestRunner.run(TestRunner.java:585)
at org.testng.SuiteRunner.runTest(SuiteRunner.java:384)
at org.testng.SuiteRunner.runSequentially(SuiteRunner.java:378)
at org.testng.SuiteRunner.privateRun(SuiteRunner.java:337)
at org.testng.SuiteRunner.run(SuiteRunner.java:286)
at org.testng.SuiteRunnerWorker.runSuite(SuiteRunnerWorker.java:53)
at org.testng.SuiteRunnerWorker.run(SuiteRunnerWorker.java:96)
at org.testng.TestNG.runSuitesSequentially(TestNG.java:1218)
at org.testng.TestNG.runSuitesLocally(TestNG.java:1140)
at org.testng.TestNG.runSuites(TestNG.java:1069)
at org.testng.TestNG.run(TestNG.java:1037)
at org.testng.remote.AbstractRemoteTestNG.run(AbstractRemoteTestNG.java:115)
at org.testng.remote.RemoteTestNG.initAndRun(RemoteTestNG.java:251)
at org.testng.remote.RemoteTestNG.main(RemoteTestNG.java:77)
]]>
            </full-stacktrace>
          </exception> <!-- java.lang.AssertionError -->
          <reporter-output>
          </reporter-output>
        </test-method> <!-- testLoginWithValidCredentials -->
        <test-method is-config="true" signature="afterMethod(org.testng.ITestResult)[pri:0, instance:com.autopractice.tests.DpTest@31c88ec8]" started-at="2020-11-29T18:41:34 GMT" name="afterMethod" finished-at="2020-11-29T18:41:34 GMT" duration-ms="1" status="PASS">
          <params>
            <param index="0">
              <value>
                <![CDATA[[TestResult name=testLoginWithValidCredentials status=FAILURE method=DpTest.testLoginWithValidCredentials(java.lang.String, java.lang.String)[pri:0, instance:com.autopractice.tests.DpTest@31c88ec8] output={null}]]]>
              </value>
            </param>
          </params>
          <reporter-output>
          </reporter-output>
        </test-method> <!-- afterMethod -->
        <test-method is-config="true" signature="enterURL()[pri:0, instance:com.autopractice.tests.DpTest@31c88ec8]" started-at="2020-11-29T18:41:34 GMT" name="enterURL" finished-at="2020-11-29T18:41:35 GMT" duration-ms="1084" status="PASS">
          <reporter-output>
          </reporter-output>
        </test-method> <!-- enterURL -->
        <test-method signature="testLoginWithValidCredentials(java.lang.String, java.lang.String)[pri:0, instance:com.autopractice.tests.DpTest@31c88ec8]" started-at="2020-11-29T18:41:35 GMT" name="testLoginWithValidCredentials" data-provider="UserData" finished-at="2020-11-29T18:41:37 GMT" duration-ms="1520" status="FAIL">
          <params>
            <param index="0">
              <value>
                <![CDATA[test2]]>
              </value>
            </param>
            <param index="1">
              <value>
                <![CDATA[pass2]]>
              </value>
            </param>
          </params>
          <exception class="java.lang.AssertionError">
            <message>
              <![CDATA[The following asserts failed:
expected [My Account - My Store] but found [Login - My Store]]]>
            </message>
            <full-stacktrace>
              <![CDATA[java.lang.AssertionError: The following asserts failed:
expected [My Account - My Store] but found [Login - My Store]
at org.testng.asserts.SoftAssert.assertAll(SoftAssert.java:47)
at org.testng.asserts.SoftAssert.assertAll(SoftAssert.java:31)
at com.autopractice.tests.DpTest.testLoginWithValidCredentials(DpTest.java:76)
at java.base/jdk.internal.reflect.NativeMethodAccessorImpl.invoke0(Native Method)
at java.base/jdk.internal.reflect.NativeMethodAccessorImpl.invoke(NativeMethodAccessorImpl.java:62)
at java.base/jdk.internal.reflect.DelegatingMethodAccessorImpl.invoke(DelegatingMethodAccessorImpl.java:43)
at java.base/java.lang.reflect.Method.invoke(Method.java:564)
at org.testng.internal.MethodInvocationHelper.invokeMethod(MethodInvocationHelper.java:132)
at org.testng.internal.TestInvoker.invokeMethod(TestInvoker.java:599)
at org.testng.internal.TestInvoker.invokeTestMethod(TestInvoker.java:174)
at org.testng.internal.MethodRunner.runInSequence(MethodRunner.java:46)
at org.testng.internal.TestInvoker$MethodInvocationAgent.invoke(TestInvoker.java:822)
at org.testng.internal.TestInvoker.invokeTestMethods(TestInvoker.java:147)
at org.testng.internal.TestMethodWorker.invokeTestMethods(TestMethodWorker.java:146)
at org.testng.internal.TestMethodWorker.run(TestMethodWorker.java:128)
at java.base/java.util.ArrayList.forEach(ArrayList.java:1511)
at org.testng.TestRunner.privateRun(TestRunner.java:764)
at org.testng.TestRunner.run(TestRunner.java:585)
at org.testng.SuiteRunner.runTest(SuiteRunner.java:384)
at org.testng.SuiteRunner.runSequentially(SuiteRunner.java:378)
at org.testng.SuiteRunner.privateRun(SuiteRunner.java:337)
at org.testng.SuiteRunner.run(SuiteRunner.java:286)
at org.testng.SuiteRunnerWorker.runSuite(SuiteRunnerWorker.java:53)
at org.testng.SuiteRunnerWorker.run(SuiteRunnerWorker.java:96)
at org.testng.TestNG.runSuitesSequentially(TestNG.java:1218)
at org.testng.TestNG.runSuitesLocally(TestNG.java:1140)
at org.testng.TestNG.runSuites(TestNG.java:1069)
at org.testng.TestNG.run(TestNG.java:1037)
at org.testng.remote.AbstractRemoteTestNG.run(AbstractRemoteTestNG.java:115)
at org.testng.remote.RemoteTestNG.initAndRun(RemoteTestNG.java:251)
at org.testng.remote.RemoteTestNG.main(RemoteTestNG.java:77)
]]>
            </full-stacktrace>
          </exception> <!-- java.lang.AssertionError -->
          <reporter-output>
          </reporter-output>
        </test-method> <!-- testLoginWithValidCredentials -->
        <test-method is-config="true" signature="afterMethod(org.testng.ITestResult)[pri:0, instance:com.autopractice.tests.DpTest@31c88ec8]" started-at="2020-11-29T18:41:37 GMT" name="afterMethod" finished-at="2020-11-29T18:41:37 GMT" duration-ms="0" status="PASS">
          <params>
            <param index="0">
              <value>
                <![CDATA[[TestResult name=testLoginWithValidCredentials status=FAILURE method=DpTest.testLoginWithValidCredentials(java.lang.String, java.lang.String)[pri:0, instance:com.autopractice.tests.DpTest@31c88ec8] output={null}]]]>
              </value>
            </param>
          </params>
          <reporter-output>
          </reporter-output>
        </test-method> <!-- afterMethod -->
        <test-method is-config="true" signature="enterURL()[pri:0, instance:com.autopractice.tests.DpTest@31c88ec8]" started-at="2020-11-29T18:41:37 GMT" name="enterURL" finished-at="2020-11-29T18:41:38 GMT" duration-ms="888" status="PASS">
          <reporter-output>
          </reporter-output>
        </test-method> <!-- enterURL -->
        <test-method signature="testLoginWithValidCredentials(java.lang.String, java.lang.String)[pri:0, instance:com.autopractice.tests.DpTest@31c88ec8]" started-at="2020-11-29T18:41:38 GMT" name="testLoginWithValidCredentials" data-provider="UserData" finished-at="2020-11-29T18:41:39 GMT" duration-ms="1053" status="FAIL">
          <params>
            <param index="0">
              <value>
                <![CDATA[test3]]>
              </value>
            </param>
            <param index="1">
              <value>
                <![CDATA[pass3]]>
              </value>
            </param>
          </params>
          <exception class="java.lang.AssertionError">
            <message>
              <![CDATA[The following asserts failed:
expected [My Account - My Store] but found [Login - My Store]]]>
            </message>
            <full-stacktrace>
              <![CDATA[java.lang.AssertionError: The following asserts failed:
expected [My Account - My Store] but found [Login - My Store]
at org.testng.asserts.SoftAssert.assertAll(SoftAssert.java:47)
at org.testng.asserts.SoftAssert.assertAll(SoftAssert.java:31)
at com.autopractice.tests.DpTest.testLoginWithValidCredentials(DpTest.java:76)
at java.base/jdk.internal.reflect.NativeMethodAccessorImpl.invoke0(Native Method)
at java.base/jdk.internal.reflect.NativeMethodAccessorImpl.invoke(NativeMethodAccessorImpl.java:62)
at java.base/jdk.internal.reflect.DelegatingMethodAccessorImpl.invoke(DelegatingMethodAccessorImpl.java:43)
at java.base/java.lang.reflect.Method.invoke(Method.java:564)
at org.testng.internal.MethodInvocationHelper.invokeMethod(MethodInvocationHelper.java:132)
at org.testng.internal.TestInvoker.invokeMethod(TestInvoker.java:599)
at org.testng.internal.TestInvoker.invokeTestMethod(TestInvoker.java:174)
at org.testng.internal.MethodRunner.runInSequence(MethodRunner.java:46)
at org.testng.internal.TestInvoker$MethodInvocationAgent.invoke(TestInvoker.java:822)
at org.testng.internal.TestInvoker.invokeTestMethods(TestInvoker.java:147)
at org.testng.internal.TestMethodWorker.invokeTestMethods(TestMethodWorker.java:146)
at org.testng.internal.TestMethodWorker.run(TestMethodWorker.java:128)
at java.base/java.util.ArrayList.forEach(ArrayList.java:1511)
at org.testng.TestRunner.privateRun(TestRunner.java:764)
at org.testng.TestRunner.run(TestRunner.java:585)
at org.testng.SuiteRunner.runTest(SuiteRunner.java:384)
at org.testng.SuiteRunner.runSequentially(SuiteRunner.java:378)
at org.testng.SuiteRunner.privateRun(SuiteRunner.java:337)
at org.testng.SuiteRunner.run(SuiteRunner.java:286)
at org.testng.SuiteRunnerWorker.runSuite(SuiteRunnerWorker.java:53)
at org.testng.SuiteRunnerWorker.run(SuiteRunnerWorker.java:96)
at org.testng.TestNG.runSuitesSequentially(TestNG.java:1218)
at org.testng.TestNG.runSuitesLocally(TestNG.java:1140)
at org.testng.TestNG.runSuites(TestNG.java:1069)
at org.testng.TestNG.run(TestNG.java:1037)
at org.testng.remote.AbstractRemoteTestNG.run(AbstractRemoteTestNG.java:115)
at org.testng.remote.RemoteTestNG.initAndRun(RemoteTestNG.java:251)
at org.testng.remote.RemoteTestNG.main(RemoteTestNG.java:77)
]]>
            </full-stacktrace>
          </exception> <!-- java.lang.AssertionError -->
          <reporter-output>
          </reporter-output>
        </test-method> <!-- testLoginWithValidCredentials -->
        <test-method is-config="true" signature="afterMethod(org.testng.ITestResult)[pri:0, instance:com.autopractice.tests.DpTest@31c88ec8]" started-at="2020-11-29T18:41:39 GMT" name="afterMethod" finished-at="2020-11-29T18:41:39 GMT" duration-ms="1" status="PASS">
          <params>
            <param index="0">
              <value>
                <![CDATA[[TestResult name=testLoginWithValidCredentials status=FAILURE method=DpTest.testLoginWithValidCredentials(java.lang.String, java.lang.String)[pri:0, instance:com.autopractice.tests.DpTest@31c88ec8] output={null}]]]>
              </value>
            </param>
          </params>
          <reporter-output>
          </reporter-output>
        </test-method> <!-- afterMethod -->
        <test-method is-config="true" signature="enterURL()[pri:0, instance:com.autopractice.tests.DpTest@31c88ec8]" started-at="2020-11-29T18:41:39 GMT" name="enterURL" finished-at="2020-11-29T18:41:40 GMT" duration-ms="860" status="PASS">
          <reporter-output>
          </reporter-output>
        </test-method> <!-- enterURL -->
        <test-method signature="testLoginWithValidCredentials(java.lang.String, java.lang.String)[pri:0, instance:com.autopractice.tests.DpTest@31c88ec8]" started-at="2020-11-29T18:41:40 GMT" name="testLoginWithValidCredentials" data-provider="UserData" finished-at="2020-11-29T18:41:41 GMT" duration-ms="974" status="FAIL">
          <params>
            <param index="0">
              <value>
                <![CDATA[test4]]>
              </value>
            </param>
            <param index="1">
              <value>
                <![CDATA[pass4]]>
              </value>
            </param>
          </params>
          <exception class="java.lang.AssertionError">
            <message>
              <![CDATA[The following asserts failed:
expected [My Account - My Store] but found [Login - My Store]]]>
            </message>
            <full-stacktrace>
              <![CDATA[java.lang.AssertionError: The following asserts failed:
expected [My Account - My Store] but found [Login - My Store]
at org.testng.asserts.SoftAssert.assertAll(SoftAssert.java:47)
at org.testng.asserts.SoftAssert.assertAll(SoftAssert.java:31)
at com.autopractice.tests.DpTest.testLoginWithValidCredentials(DpTest.java:76)
at java.base/jdk.internal.reflect.NativeMethodAccessorImpl.invoke0(Native Method)
at java.base/jdk.internal.reflect.NativeMethodAccessorImpl.invoke(NativeMethodAccessorImpl.java:62)
at java.base/jdk.internal.reflect.DelegatingMethodAccessorImpl.invoke(DelegatingMethodAccessorImpl.java:43)
at java.base/java.lang.reflect.Method.invoke(Method.java:564)
at org.testng.internal.MethodInvocationHelper.invokeMethod(MethodInvocationHelper.java:132)
at org.testng.internal.TestInvoker.invokeMethod(TestInvoker.java:599)
at org.testng.internal.TestInvoker.invokeTestMethod(TestInvoker.java:174)
at org.testng.internal.MethodRunner.runInSequence(MethodRunner.java:46)
at org.testng.internal.TestInvoker$MethodInvocationAgent.invoke(TestInvoker.java:822)
at org.testng.internal.TestInvoker.invokeTestMethods(TestInvoker.java:147)
at org.testng.internal.TestMethodWorker.invokeTestMethods(TestMethodWorker.java:146)
at org.testng.internal.TestMethodWorker.run(TestMethodWorker.java:128)
at java.base/java.util.ArrayList.forEach(ArrayList.java:1511)
at org.testng.TestRunner.privateRun(TestRunner.java:764)
at org.testng.TestRunner.run(TestRunner.java:585)
at org.testng.SuiteRunner.runTest(SuiteRunner.java:384)
at org.testng.SuiteRunner.runSequentially(SuiteRunner.java:378)
at org.testng.SuiteRunner.privateRun(SuiteRunner.java:337)
at org.testng.SuiteRunner.run(SuiteRunner.java:286)
at org.testng.SuiteRunnerWorker.runSuite(SuiteRunnerWorker.java:53)
at org.testng.SuiteRunnerWorker.run(SuiteRunnerWorker.java:96)
at org.testng.TestNG.runSuitesSequentially(TestNG.java:1218)
at org.testng.TestNG.runSuitesLocally(TestNG.java:1140)
at org.testng.TestNG.runSuites(TestNG.java:1069)
at org.testng.TestNG.run(TestNG.java:1037)
at org.testng.remote.AbstractRemoteTestNG.run(AbstractRemoteTestNG.java:115)
at org.testng.remote.RemoteTestNG.initAndRun(RemoteTestNG.java:251)
at org.testng.remote.RemoteTestNG.main(RemoteTestNG.java:77)
]]>
            </full-stacktrace>
          </exception> <!-- java.lang.AssertionError -->
          <reporter-output>
          </reporter-output>
        </test-method> <!-- testLoginWithValidCredentials -->
        <test-method is-config="true" signature="afterMethod(org.testng.ITestResult)[pri:0, instance:com.autopractice.tests.DpTest@31c88ec8]" started-at="2020-11-29T18:41:41 GMT" name="afterMethod" finished-at="2020-11-29T18:41:41 GMT" duration-ms="1" status="PASS">
          <params>
            <param index="0">
              <value>
                <![CDATA[[TestResult name=testLoginWithValidCredentials status=FAILURE method=DpTest.testLoginWithValidCredentials(java.lang.String, java.lang.String)[pri:0, instance:com.autopractice.tests.DpTest@31c88ec8] output={null}]]]>
              </value>
            </param>
          </params>
          <reporter-output>
          </reporter-output>
        </test-method> <!-- afterMethod -->
        <test-method is-config="true" signature="closeBrowser()[pri:0, instance:com.autopractice.tests.DpTest@31c88ec8]" started-at="2020-11-29T18:41:41 GMT" name="closeBrowser" finished-at="2020-11-29T18:41:41 GMT" duration-ms="60" status="PASS">
          <reporter-output>
          </reporter-output>
        </test-method> <!-- closeBrowser -->
      </class> <!-- com.autopractice.tests.DpTest -->
    </test> <!-- Default test -->
  </suite> <!-- Default suite -->
</testng-results>
